Workbook

Sheet US Overview
A1: US FISCAL ACCOUNTING — RAW -> BVAR -> RECURSION -> PROJECTION
A3: THE TARGET CONCEPT
A4: User's level form | B4: B_t = Exp_t - Rev_t + (1 + i_eff_t)*B_{t-1}, then d_t = B_t / GDP_t. Exp = PRIMARY expenditure (EXCLUDES interest). Rev = revenue. i_eff = effective rate on the debt stock. B = debt stock (level). The interest cost sits entirely in the (1+i_eff)*B_{t-1} term. d = B/GDP.
A5: App's ratio form (per quarter) | B5: d_t = d_{t-1}*(1 + i_eff/400)/(1 + gNomQ/100) - pb/4 (% of GDP; i_eff %/yr; gNomQ %/quarter; pb = rev - primexp). This is the user's level form rewritten in ratio space and quarterised - the SAME identity. The 'Fiscal Arithmetic' sheet proves the two land on the identical debt/GDP, column by column.
A7: THE THREE BVAR FISCAL DRIVERS (estimated)
A8: FREV_GDP | B8: Revenue / GDP * 100 (% of GDP). BVAR 'lin' variable.
A9: FPEXP_GDP | B9: (Expenditure - interest) / GDP * 100 = PRIMARY expenditure / GDP (% of GDP). 'lin'.
A10: DSVC | B10: Debt service / GDP * 100 = net interest / LAGGED GDP (% of GDP). 'lin'. THIS is forecast by the BVAR; the effective rate i_eff is BACKED OUT from it as i_eff = DSVC*100 / d_{t-1}.
A11: (internal) EFFI | B11: Effective interest rate = net interest / LAGGED debt stock * 100 (% p.a.). DSVC = EFFI * d_{t-1}/100, i.e. debt service = the effective rate applied to last quarter's debt ratio.
A13: THE FIVE SHEETS PER COUNTRY
A14: Raw Data | B14: the raw series in levels, with charts.
A15: Construction | B15: builds FREV_GDP, FPEXP_GDP, EFFI and DSVC from the raw cells with LIVE formulas.
A16: Fiscal Arithmetic | B16: reconstructs HISTORICAL debt/GDP from the flows (back-cast check vs observed).
A17: Projection | B17: how the BVAR projects DSVC (debt service) and debt/GDP AHEAD, with 16/84 bands.
A19: RAW SERIES & SOURCES
A20: Raw series (role) | B20: Source ID / provenance, units
A21: nominal GDP | B21: FRED: GDP - nominal GDP, $bn SAAR
A22: federal receipts | B22: FRED: FGRECPT - federal current receipts, $bn SAAR
A23: federal expenditure | B23: FRED: FGEXPND - federal current expenditures (INCL. interest), $bn SAAR
A24: federal net interest | B24: FRED: A091RC1Q027SBEA - federal interest payments, $bn SAAR
A25: gross federal debt | B25: FRED: GFDEGDQ188S - gross federal debt as % of GDP (the d0 anchor)
A27: UNIT CONVENTIONS
A28: SAAR (US flows) | B28: GDP/FGRECPT/FGEXPND/A091 are Seasonally-Adjusted ANNUAL RATES: each quarter already states an annual $-rate, so a ratio is flow_t / GDP_t with NO *4.
A29: Quarterly levels (UK flows) | B29: ONS revenue/expenditure/interest are quarterly LEVELS (GBP m, not annualised), so the ratio uses a 4-QUARTER TRAILING SUM: 4q-sum(flow)/4q-sum(GDP).
A30: % of GDP (annual ratio) | B30: FREV_GDP, FPEXP_GDP, DSVC are annual ratios, e.g. 18 means 18% of GDP. Carried in the BVAR as 'lin' (level) variables.
A31: Effective rate | B31: EFFI is %/year on the debt STOCK (e.g. 3 = 3%/yr); NOT the policy or market yield.
A32: Debt / GDP (d) | B32: d, d0 in %, e.g. 100 = 100% of GDP. This workbook's US d0 = 122.5682%.
A33: Nominal growth gNomQ | B33: %/QUARTER. US: from SAAR GDP (already annual). UK: from the 4q-GDP base (same base the ratio uses). The forecast uses Delta(real 100*log GDP) + Delta(deflator 100*log).
A35: COVID NOTE (US only): the deployed BVAR linearly interpolates FPEXP_GDP across the SAME 7 quarters it carries, 2020Q2-2021Q4, to remove the CARES/ARP emergency-spending spike (raw 2020Q2 FPEXP ~42% of GDP vs a ~20% norm). US flows are SAAR, so there is NO annual-window lag: the treated quarters ARE the BVAR's quarters. The Construction sheet shows BOTH the raw (no-COVID) FPEXP and the value that actually entered the BVAR. FREV and DSVC are untreated. The UK gets no COVID treatment (raw == deployed).
A36: SPOT-CHECK vs the deployed BVAR app/public/data/bvar/US: US 2025Q4 (last history): FREV_GDP=18.7715, FPEXP_GDP=20.2281, DSVC=3.9472 - MATCH historical.json cols 33/34/35 exactly. All 40 quarters match to <1e-4, except the 7 COVID quarters 2020Q2-2021Q4 where the into-BVAR FPEXP is interpolated (raw 2020Q2 FPEXP=41.97 vs into-BVAR 20.04). BVAR projects DSVC 3.96 -> 4.92% of GDP over 20 quarters (see US Projection).

Sheet US Raw Data
A1: US RAW DATA - FRED quarterly (SAAR flows; debt as % of GDP)
A3: Date | B3: GDP ($bn, SAAR) | C3: FGRECPT receipts ($bn, SAAR) | D3: FGEXPND expenditure ($bn, SAAR) | E3: A091 net interest ($bn, SAAR) | F3: GFDEGDQ188S gross debt (% of GDP)
B4: FRED: GDP | C4: FRED: FGRECPT | D4: FRED: FGEXPND | E4: FRED: A091RC1Q027SBEA | F4: FRED: GFDEGDQ188S
A5: 1998-Q2 | B5: 8969.699 | C5: 1771.548 | D5: 1781.911 | E5: 367.648 | F5: 61.85196
A6: 1998-Q3 | B6: 9121.097 | C6: 1808.447 | D6: 1788.538 | E6: 366.204 | F6: 60.58693
A7: 1998-Q4 | B7: 9293.991 | C7: 1835.085 | D7: 1814.518 | E7: 360.088 | F7: 60.40696
A8: 1999-Q1 | B8: 9411.682 | C8: 1860.002 | D8: 1811.988 | E8: 352.596 | F8: 60.04894
A9: 1999-Q2 | B9: 9526.21 | C9: 1885.184 | D9: 1816.961 | E9: 352.141 | F9: 59.19227
A10: 1999-Q3 | B10: 9686.626 | C10: 1914.862 | D10: 1843.205 | E10: 351.073 | F10: 58.39258
A11: 1999-Q4 | B11: 9900.169 | C11: 1963.756 | D11: 1875.154 | E11: 352.925 | F11: 58.34336
A12: 2000-Q1 | B12: 10002.179 | C12: 2041.764 | D12: 1866.308 | E12: 354.822 | F12: 57.72134
A13: 2000-Q2 | B13: 10247.72 | C13: 2056.279 | D13: 1908.645 | E13: 354.109 | F13: 55.48491
A14: 2000-Q3 | B14: 10318.165 | C14: 2076.268 | D14: 1918.617 | E14: 352.877 | F14: 54.99213
A15: 2000-Q4 | B15: 10435.744 | C15: 2096.796 | D15: 1938.796 | E15: 353.105 | F15: 54.2579
A16: 2001-Q1 | B16: 10470.231 | C16: 2111.058 | D16: 1982.626 | E16: 345.479 | F16: 55.14434
... A115: 2025-Q4 | B115: 31422.526 | C115: 5898.479 | D115: 7583.663 | E115: 1227.495 | F115: 122.56815

Sheet US Raw Data_nsa
A1: US RAW DATA - FRED quarterly (SAAR flows; debt as % of GDP)
A3: Date | B3: Gross Domestic Product (NA000334Q),Millions of Dollars, Not Seasonally Adjusted | C3: Federal Government Current Receipts (NA000304Q), Millions of Dollars, Not Seasonally Adjusted | D3: Federal Government: Current Expenditures (NA000283Q), Millions of Dollars, Not Seasonally Adjusted | E3: Federal government current expenditures: Interest payments (NA000308Q), Millions of Dollars, Not Seasonally Adjusted | F3: GFDEBTN - Federal Debt: Total Public Debt (GFDEBTN), Millions of Dollars, Not Seasonally Adjusted
B4: FRED: NA000334Q | C4: FRED: NA000304Q | D4: FRED: NA000283Q | E4: FRED: NA000308Q | F4: FRED: GFDEBTN
A5: 1998-Q2 | B5: 2249908 | C5: 455865 | D5: 445251 | E5: 91910 | F5: 5547935
A6: 1998-Q3 | B6: 2281422 | C6: 456297 | D6: 443702 | E6: 91551 | F6: 5526193
A7: 1998-Q4 | B7: 2370677 | C7: 450491 | D7: 460154 | E7: 90022 | F7: 5614217
A8: 1999-Q1 | B8: 2293136 | C8: 451584 | D8: 448286 | E8: 88149 | F8: 5651615
A9: 1999-Q2 | B9: 2388422 | C9: 486768 | D9: 456605 | E9: 88035 | F9: 5638780
A10: 1999-Q3 | B10: 2423648 | C10: 483561 | D10: 458196 | E10: 87768 | F10: 5656271
A11: 1999-Q4 | B11: 2524828 | C11: 484037 | D11: 473741 | E11: 88231 | F11: 5776091
A12: 2000-Q1 | B12: 2448892 | C12: 499364 | D12: 468041 | E12: 88705 | F12: 5773392
A13: 2000-Q2 | B13: 2569266 | C13: 531105 | D13: 479183 | E13: 88527 | F13: 5685938
A14: 2000-Q3 | B14: 2577927 | C14: 522953 | D14: 472437 | E14: 88219 | F14: 5674179
A15: 2000-Q4 | B15: 2655636 | C15: 514356 | D15: 488430 | E15: 88276 | F15: 5662216
A16: 2001-Q1 | B16: 2562488 | C16: 511352 | D16: 497170 | E16: 86370 | F16: 5773740
... A115: 2025-Q4 | B115: 7971751 | C115: 1501013 | D115: 1892982 | E115: 306874 | F115: 38514009
B116: 7764730 | D116: 1914942 | E116: 304734

Sheet UScalc_nsa
A1: Quarter | B1: GDPN | C1: TAX | D1: GEXP+INTEXP | E1: INTEXP | F1: GEXP | G1: DEBT | H1: DEBTCheck1 | I1: RESID | J1: DEBTCheck2 | K1: DEBTCheck3 | M1: GEXPSHR | N1: TAXSHR | O1: DEBTG | P1: DEBTGL | Q1: Ieff | R1: FFLOWSHR | S1: DEBTcheck Static | T1: DEBTcheck Dynamic | AF1: Is DEBTG end of period?
A2: ='US Raw Data_nsa'!A5 -> 1998-Q2 | B2: ='US Raw Data_nsa'!B5 -> 2249908 | C2: ='US Raw Data_nsa'!C5 -> 455865 | D2: ='US Raw Data_nsa'!D5 -> 445251 | E2: ='US Raw Data_nsa'!E5 -> 91910 | F2: =D2-E2 -> 353341 | G2: ='US Raw Data_nsa'!F5 -> 5547935 | M2: =400*F2/(4*B2) -> 15.704687 | N2: =400*C2/(4*B2) -> 20.261495 | O2: =100*G2/(4*B2) -> 61.646243 | P2: NaN | Q2: NaN | R2: NaN | T2: GDP(t-1) | U2: GDP(t) | AF2: Are expenditures includig or excluding interest rate component?
A3: ='US Raw Data_nsa'!A6 -> 1998-Q3 | B3: ='US Raw Data_nsa'!B6 -> 2281422 | C3: ='US Raw Data_nsa'!C6 -> 456297 | D3: ='US Raw Data_nsa'!D6 -> 443702 | E3: ='US Raw Data_nsa'!E6 -> 91551 | F3: =D3-E3 -> 352151 | G3: ='US Raw Data_nsa'!F6 -> 5526193 | H3: =F3-C3+E3+G2 -> 5535340 | I3: =G3-H3 -> -9147 | J3: =F3-C3+E3+G2 -> 5535340 | K3: =F3-C3+E3+I3+G2 -> 5526193 | M3: =400*F3/(4*B3) -> 15.435592 | N3: =400*C3/(4*B3) -> 20.000552 | O3: =100*G3/(4*B3) -> 60.556453 | P3: =100*G2/(4*B3) -> 60.794704 | Q3: =400*E3/(4*B3)*(1/(P3/100)) -> 6.6007262 | R3: =400*I3/(4*B3) -> -0.40093415 | S3: =(1/4)*(M3-N3+R3)+(1+(Q3/400))*P3 -> 60.556453 | T3: =(1/4)*(M3-N3+R3)+(1+(Q3/400))*P3 -> 60.556453
A4: ='US Raw Data_nsa'!A7 -> 1998-Q4 | B4: ='US Raw Data_nsa'!B7 -> 2370677 | C4: ='US Raw Data_nsa'!C7 -> 450491 | D4: ='US Raw Data_nsa'!D7 -> 460154 | E4: ='US Raw Data_nsa'!E7 -> 90022 | F4: =D4-E4 -> 370132 | G4: ='US Raw Data_nsa'!F7 -> 5614217 | H4: =F4-C4+E4+G3 -> 5535856 | I4: =G4-H4 -> 78361 | J4: =F4-C4+E4+J3 -> 5545003 | K4: =F4-C4+E4+I4+K3 -> 5614217 | M4: =400*F4/(4*B4) -> 15.612924 | N4: =400*C4/(4*B4) -> 19.002631 | O4: =100*G4/(4*B4) -> 59.204786 | P4: =100*G3/(4*B4) -> 58.276528 | Q4: =400*E4/(4*B4)*(1/(P4/100)) -> 6.5160229 | R4: =400*I4/(4*B4) -> 3.3054271 | S4: =(1/4)*(M4-N4+R4)+(1+(Q4/400))*P4 -> 59.204786 | T4: =(1/4)*(M4-N4+R4)+(1+(Q4/400))*T3 -> 61.521852 | U4: =T4*(B3/B4) -> 59.20558
A5: ='US Raw Data_nsa'!A8 -> 1999-Q1 | B5: ='US Raw Data_nsa'!B8 -> 2293136 | C5: ='US Raw Data_nsa'!C8 -> 451584 | D5: ='US Raw Data_nsa'!D8 -> 448286 | E5: ='US Raw Data_nsa'!E8 -> 88149 | F5: =D5-E5 -> 360137 | G5: ='US Raw Data_nsa'!F8 -> 5651615 | H5: =F5-C5+E5+G4 -> 5610919 | I5: =G5-H5 -> 40696 | J5: =F5-C5+E5+J4 -> 5541705 | K5: =F5-C5+E5+I5+K4 -> 5651615 | M5: =400*F5/(4*B5) -> 15.705 | N5: =400*C5/(4*B5) -> 19.692857 | O5: =100*G5/(4*B5) -> 61.614477 | P5: =100*G4/(4*B5) -> 61.20676 | Q5: =400*E5/(4*B5)*(1/(P5/100)) -> 6.2804127 | R5: =400*I5/(4*B5) -> 1.7746876 | S5: =(1/4)*(M5-N5+R5)+(1+(Q5/400))*P5 -> 61.614477 | T5: =(1/4)*(M5-N5+R5)+(1+(Q5/400))*U4 -> 59.581876 | U5: =T5*(B4/B5) -> 61.596601
A6: ='US Raw Data_nsa'!A9 -> 1999-Q2 | B6: ='US Raw Data_nsa'!B9 -> 2388422 | C6: ='US Raw Data_nsa'!C9 -> 486768 | D6: ='US Raw Data_nsa'!D9 -> 456605 | E6: ='US Raw Data_nsa'!E9 -> 88035 | F6: =D6-E6 -> 368570 | G6: ='US Raw Data_nsa'!F9 -> 5638780 | H6: =F6-C6+E6+G5 -> 5621452 | I6: =G6-H6 -> 17328 | J6: =F6-C6+E6+J5 -> 5511542 | K6: =F6-C6+E6+I6+K5 -> 5638780 | M6: =400*F6/(4*B6) -> 15.431528 | N6: =400*C6/(4*B6) -> 20.380318 | O6: =100*G6/(4*B6) -> 59.022024 | P6: =100*G5/(4*B6) -> 59.15637 | Q6: =400*E6/(4*B6)*(1/(P6/100)) -> 6.2307854 | R6: =400*I6/(4*B6) -> 0.72549993 | S6: =(1/4)*(M6-N6+R6)+(1+(Q6/400))*P6 -> 59.022024 | T6: =(1/4)*(M6-N6+R6)+(1+(Q6/400))*U5 -> 61.500266 | U6: =T6*(B5/B6) -> 59.046715
A7: ='US Raw Data_nsa'!A10 -> 1999-Q3 | B7: ='US Raw Data_nsa'!B10 -> 2423648 | C7: ='US Raw Data_nsa'!C10 -> 483561 | D7: ='US Raw Data_nsa'!D10 -> 458196 | E7: ='US Raw Data_nsa'!E10 -> 87768 | F7: =D7-E7 -> 370428 | G7: ='US Raw Data_nsa'!F10 -> 5656271 | H7: =F7-C7+E7+G6 -> 5613415 | I7: =G7-H7 -> 42856 | J7: =F7-C7+E7+J6 -> 5486177 | K7: =F7-C7+E7+I7+K6 -> 5656271 | M7: =400*F7/(4*B7) -> 15.283903 | N7: =400*C7/(4*B7) -> 19.951783 | O7: =100*G7/(4*B7) -> 58.344601 | P7: =100*G6/(4*B7) -> 58.164181 | Q7: =400*E7/(4*B7)*(1/(P7/100)) -> 6.2260276 | R7: =400*I7/(4*B7) -> 1.7682436 | S7: =(1/4)*(M7-N7+R7)+(1+(Q7/400))*P7 -> 58.344601 | T7: =(1/4)*(M7-N7+R7)+(1+(Q7/400))*U6 -> 59.240872 | U7: =T7*(B6/B7) -> 58.379848
A8: ='US Raw Data_nsa'!A11 -> 1999-Q4 | B8: ='US Raw Data_nsa'!B11 -> 2524828 | C8: ='US Raw Data_nsa'!C11 -> 484037 | D8: ='US Raw Data_nsa'!D11 -> 473741 | E8: ='US Raw Data_nsa'!E11 -> 88231 | F8: =D8-E8 -> 385510 | G8: ='US Raw Data_nsa'!F11 -> 5776091 | H8: =F8-C8+E8+G7 -> 5645975 | I8: =G8-H8 -> 130116 | J8: =F8-C8+E8+J7 -> 5475881 | K8: =F8-C8+E8+I8+K7 -> 5776091 | M8: =400*F8/(4*B8) -> 15.268763 | N8: =400*C8/(4*B8) -> 19.171088 | O8: =100*G8/(4*B8) -> 57.192916 | P8: =100*G7/(4*B8) -> 56.006498 | Q8: =400*E8/(4*B8)*(1/(P8/100)) -> 6.2395172 | R8: =400*I8/(4*B8) -> 5.15346 | S8: =(1/4)*(M8-N8+R8)+(1+(Q8/400))*P8 -> 57.192916 | T8: =(1/4)*(M8-N8+R8)+(1+(Q8/400))*U7 -> 59.603287 | U8: =T8*(B7/B8) -> 57.214744
A9: ='US Raw Data_nsa'!A12 -> 2000-Q1 | B9: ='US Raw Data_nsa'!B12 -> 2448892 | C9: ='US Raw Data_nsa'!C12 -> 499364 | D9: ='US Raw Data_nsa'!D12 -> 468041 | E9: ='US Raw Data_nsa'!E12 -> 88705 | F9: =D9-E9 -> 379336 | G9: ='US Raw Data_nsa'!F12 -> 5773392 | H9: =F9-C9+E9+G8 -> 5744768 | I9: =G9-H9 -> 28624 | J9: =F9-C9+E9+J8 -> 5444558 | K9: =F9-C9+E9+I9+K8 -> 5773392 | M9: =400*F9/(4*B9) -> 15.490107 | N9: =400*C9/(4*B9) -> 20.391426 | O9: =100*G9/(4*B9) -> 58.938818 | P9: =100*G8/(4*B9) -> 58.966371 | Q9: =400*E9/(4*B9)*(1/(P9/100)) -> 6.1429088 | R9: =400*I9/(4*B9) -> 1.1688551 | S9: =(1/4)*(M9-N9+R9)+(1+(Q9/400))*P9 -> 58.938818 | T9: =(1/4)*(M9-N9+R9)+(1+(Q9/400))*U8 -> 57.16029 | U9: =T9*(B8/B9) -> 58.932734
A10: ='US Raw Data_nsa'!A13 -> 2000-Q2 | B10: ='US Raw Data_nsa'!B13 -> 2569266 | C10: ='US Raw Data_nsa'!C13 -> 531105 | D10: ='US Raw Data_nsa'!D13 -> 479183 | E10: ='US Raw Data_nsa'!E13 -> 88527 | F10: =D10-E10 -> 390656 | G10: ='US Raw Data_nsa'!F13 -> 5685938 | H10: =F10-C10+E10+G9 -> 5721470 | I10: =G10-H10 -> -35532 | J10: =F10-C10+E10+J9 -> 5392636 | K10: =F10-C10+E10+I10+K9 -> 5685938 | M10: =400*F10/(4*B10) -> 15.204965 | N10: =400*C10/(4*B10) -> 20.671468 | O10: =100*G10/(4*B10) -> 55.326482 | P10: =100*G9/(4*B10) -> 56.177445 | Q10: =400*E10/(4*B10)*(1/(P10/100)) -> 6.1334481 | R10: =400*I10/(4*B10) -> -1.3829631 | S10: =(1/4)*(M10-N10+R10)+(1+(Q10/400))*P10 -> 55.326482 | T10: =(1/4)*(M10-N10+R10)+(1+(Q10/400))*U9 -> 58.12402 | U10: =T10*(B9/B10) -> 55.400822
A11: ='US Raw Data_nsa'!A14 -> 2000-Q3 | B11: ='US Raw Data_nsa'!B14 -> 2577927 | C11: ='US Raw Data_nsa'!C14 -> 522953 | D11: ='US Raw Data_nsa'!D14 -> 472437 | E11: ='US Raw Data_nsa'!E14 -> 88219 | F11: =D11-E11 -> 384218 | G11: ='US Raw Data_nsa'!F14 -> 5674179 | H11: =F11-C11+E11+G10 -> 5635422 | I11: =G11-H11 -> 38757 | J11: =F11-C11+E11+J10 -> 5342120 | K11: =F11-C11+E11+I11+K10 -> 5674179 | M11: =400*F11/(4*B11) -> 14.904146 | N11: =400*C11/(4*B11) -> 20.285796 | O11: =100*G11/(4*B11) -> 55.026568 | P11: =100*G10/(4*B11) -> 55.140603 | Q11: =400*E11/(4*B11)*(1/(P11/100)) -> 6.2061176 | R11: =400*I11/(4*B11) -> 1.5034173 | S11: =(1/4)*(M11-N11+R11)+(1+(Q11/400))*P11 -> 55.026568 | T11: =(1/4)*(M11-N11+R11)+(1+(Q11/400))*U10 -> 55.290824 | U11: =T11*(B10/B11) -> 55.105064
A12: ='US Raw Data_nsa'!A15 -> 2000-Q4 | B12: ='US Raw Data_nsa'!B15 -> 2655636 | C12: ='US Raw Data_nsa'!C15 -> 514356 | D12: ='US Raw Data_nsa'!D15 -> 488430 | E12: ='US Raw Data_nsa'!E15 -> 88276 | F12: =D12-E12 -> 400154 | G12: ='US Raw Data_nsa'!F15 -> 5662216 | H12: =F12-C12+E12+G11 -> 5648253 | I12: =G12-H12 -> 13963 | J12: =F12-C12+E12+J11 -> 5316194 | K12: =F12-C12+E12+I12+K11 -> 5662216 | M12: =400*F12/(4*B12) -> 15.068104 | N12: =400*C12/(4*B12) -> 19.368468 | O12: =100*G12/(4*B12) -> 53.303766 | P12: =100*G11/(4*B12) -> 53.416385 | Q12: =400*E12/(4*B12)*(1/(P12/100)) -> 6.2229972 | R12: =400*I12/(4*B12) -> 0.52578742 | S12: =(1/4)*(M12-N12+R12)+(1+(Q12/400))*P12 -> 53.303766 | T12: =(1/4)*(M12-N12+R12)+(1+(Q12/400))*U11 -> 55.018717 | U12: =T12*(B11/B12) -> 53.408764
A13: ='US Raw Data_nsa'!A16 -> 2001-Q1 | B13: ='US Raw Data_nsa'!B16 -> 2562488 | C13: ='US Raw Data_nsa'!C16 -> 511352 | D13: ='US Raw Data_nsa'!D16 -> 497170 | E13: ='US Raw Data_nsa'!E16 -> 86370 | F13: =D13-E13 -> 410800 | G13: ='US Raw Data_nsa'!F16 -> 5773740 | H13: =F13-C13+E13+G12 -> 5648034 | I13: =G13-H13 -> 125706 | J13: =F13-C13+E13+J12 -> 5302012 | K13: =F13-C13+E13+I13+K12 -> 5773740 | M13: =400*F13/(4*B13) -> 16.031295 | N13: =400*C13/(4*B13) -> 19.955293 | O13: =100*G13/(4*B13) -> 56.329435 | P13: =100*G12/(4*B13) -> 55.24139 | Q13: =400*E13/(4*B13)*(1/(P13/100)) -> 6.1014981 | R13: =400*I13/(4*B13) -> 4.905623 | S13: =(1/4)*(M13-N13+R13)+(1+(Q13/400))*P13 -> 56.329435 | T13: =(1/4)*(M13-N13+R13)+(1+(Q13/400))*U12 -> 54.468854 | U13: =T13*(B12/B13) -> 56.44883
A14: ='US Raw Data_nsa'!A17 -> 2001-Q2 | B14: ='US Raw Data_nsa'!B17 -> 2656407 | C14: ='US Raw Data_nsa'!C17 -> 537564 | D14: ='US Raw Data_nsa'!D17 -> 503150 | E14: ='US Raw Data_nsa'!E17 -> 83694 | F14: =D14-E14 -> 419456 | G14: ='US Raw Data_nsa'!F17 -> 5726815 | H14: =F14-C14+E14+G13 -> 5739326 | I14: =G14-H14 -> -12511 | J14: =F14-C14+E14+J13 -> 5267598 | K14: =F14-C14+E14+I14+K13 -> 5726815 | M14: =400*F14/(4*B14) -> 15.790351 | N14: =400*C14/(4*B14) -> 20.236507 | O14: =100*G14/(4*B14) -> 53.89625 | P14: =100*G13/(4*B14) -> 54.337871 | Q14: =400*E14/(4*B14)*(1/(P14/100)) -> 5.7982521 | R14: =400*I14/(4*B14) -> -0.47097452 | S14: =(1/4)*(M14-N14+R14)+(1+(Q14/400))*P14 -> 53.89625 | T14: =(1/4)*(M14-N14+R14)+(1+(Q14/400))*U13 -> 56.037808 | U14: =T14*(B13/B14) -> 54.056555
A15: ='US Raw Data_nsa'!A18 -> 2001-Q3 | B15: ='US Raw Data_nsa'!B18 -> 2651366 | C15: ='US Raw Data_nsa'!C18 -> 485197 | D15: ='US Raw Data_nsa'!D18 -> 501435 | E15: ='US Raw Data_nsa'!E18 -> 81707 | F15: =D15-E15 -> 419728 | G15: ='US Raw Data_nsa'!F18 -> 5807464 | H15: =F15-C15+E15+G14 -> 5743053 | I15: =G15-H15 -> 64411 | J15: =F15-C15+E15+J14 -> 5283836 | K15: =F15-C15+E15+I15+K14 -> 5807464 | M15: =400*F15/(4*B15) -> 15.830632 | N15: =400*C15/(4*B15) -> 18.299888 | O15: =100*G15/(4*B15) -> 54.759169 | P15: =100*G14/(4*B15) -> 53.998722 | Q15: =400*E15/(4*B15)*(1/(P15/100)) -> 5.7069767 | R15: =400*I15/(4*B15) -> 2.4293515 | S15: =(1/4)*(M15-N15+R15)+(1+(Q15/400))*P15 -> 54.759169 | T15: =(1/4)*(M15-N15+R15)+(1+(Q15/400))*U14 -> 54.817828 | U15: =T15*(B14/B15) -> 54.922052
A16: ='US Raw Data_nsa'!A19 -> 2001-Q4 | B16: ='US Raw Data_nsa'!B19 -> 2711715 | C16: ='US Raw Data_nsa'!C19 -> 498255 | D16: ='US Raw Data_nsa'!D19 -> 515573 | E16: ='US Raw Data_nsa'!E19 -> 79455 | F16: =D16-E16 -> 436118 | G16: ='US Raw Data_nsa'!F19 -> 5943439 | H16: =F16-C16+E16+G15 -> 5824782 | I16: =G16-H16 -> 118657 | J16: =F16-C16+E16+J15 -> 5301154 | K16: =F16-C16+E16+I16+K15 -> 5943439 | M16: =400*F16/(4*B16) -> 16.082737 | N16: =400*C16/(4*B16) -> 18.374165 | O16: =100*G16/(4*B16) -> 54.794097 | P16: =100*G15/(4*B16) -> 53.540508 | Q16: =400*E16/(4*B16)*(1/(P16/100)) -> 5.4726125 | R16: =400*I16/(4*B16) -> 4.3757179 | S16: =(1/4)*(M16-N16+R16)+(1+(Q16/400))*P16 -> 54.794097 | T16: =(1/4)*(M16-N16+R16)+(1+(Q16/400))*U15 -> 56.194542 | U16: =T16*(B15/B16) -> 54.943937
... A112: ='US Raw Data_nsa'!A115 -> 2025-Q4 | B112: ='US Raw Data_nsa'!B115 -> 7971751 | C112: ='US Raw Data_nsa'!C115 -> 1501013 | D112: ='US Raw Data_nsa'!D115 -> 1892982 | E112: ='US Raw Data_nsa'!E115 -> 306874 | F112: =D112-E112 -> 1586108 | G112: ='US Raw Data_nsa'!F115 -> 38514009 | H112: =F112-C112+E112+G111 -> 38029522 | I112: =G112-H112 -> 484487.4 | J112: =F112-C112+E112+J111 -> 29954491 | K112: =F112-C112+E112+I112+K111 -> 38514009 | M112: =400*F112/(4*B112) -> 19.896607 | N112: =400*C112/(4*B112) -> 18.829151 | O112: =100*G112/(4*B112) -> 120.78278 | P112: =100*G111/(4*B112) -> 118.03415 | Q112: =400*E112/(4*B112)*(1/(P112/100)) -> 3.2613598 | R112: =400*I112/(4*B112) -> 6.0775532 | S112: =(1/4)*(M112-N112+R112)+(1+(Q112/400))*P112 -> 120.78278 | T112: =(1/4)*(M112-N112+R112)+(1+(Q112/400))*U111 -> 123.37637 | U112: =T112*(B111/B112) -> 120.66682

Sheet UScalc
A1: Quarter | B1: GDPN | C1: TAX | D1: GEXP+INTEXP | E1: INTEXP | F1: GEXP | G1: DEBT | H1: DEBTCheck1 | I1: RESID | J1: DEBTCheck2 | K1: DEBTCheck3 | M1: GEXPSHR | N1: TAXSHR | O1: DEBTG | P1: DEBTGL | Q1: Ieff | R1: FFLOWSHR | S1: DEBTcheck Static | T1: DEBTcheck Dynamic | AF1: Is DEBTG end of period?
A2: ='US Raw Data'!A5 -> 1998-Q2 | B2: ='US Raw Data'!B5 -> 8969.699 | C2: ='US Raw Data'!C5 -> 1771.548 | D2: ='US Raw Data'!D5 -> 1781.911 | E2: ='US Raw Data'!E5 -> 367.648 | F2: =D2-E2 -> 1414.263 | G2: ='US Raw Data'!F5*(B2*4/100) -> 22191.739 | M2: =400*F2/(4*B2) -> 15.767118 | N2: =400*C2/(4*B2) -> 19.750362 | O2: =100*G2/(4*B2) -> 61.85196 | P2: NaN | Q2: NaN | R2: NaN | T2: GDP(t-1) | U2: GDP(t) | AF2: Are expenditures includig or excluding interest rate component?
A3: ='US Raw Data'!A6 -> 1998-Q3 | B3: ='US Raw Data'!B6 -> 9121.097 | C3: ='US Raw Data'!C6 -> 1808.447 | D3: ='US Raw Data'!D6 -> 1788.538 | E3: ='US Raw Data'!E6 -> 366.204 | F3: =D3-E3 -> 1422.334 | G3: ='US Raw Data'!F6*(B3*4/100) -> 22104.771 | H3: =F3-C3+E3+G2 -> 22171.83 | I3: =G3-H3 -> -67.058932 | J3: =F3-C3+E3+G2 -> 22171.83 | K3: =F3-C3+E3+I3+G2 -> 22104.771 | M3: =400*F3/(4*B3) -> 15.593892 | N3: =400*C3/(4*B3) -> 19.827078 | O3: =100*G3/(4*B3) -> 60.58693 | P3: =100*G2/(4*B3) -> 60.8253 | Q3: =400*E3/(4*B3)*(1/(P3/100)) -> 6.6007266 | R3: =400*I3/(4*B3) -> -0.73520687 | S3: =(1/4)*(M3-N3+R3)+(1+(Q3/400))*P3 -> 60.58693 | T3: =(1/4)*(M3-N3+R3)+(1+(Q3/400))*P3 -> 60.58693
A4: ='US Raw Data'!A7 -> 1998-Q4 | B4: ='US Raw Data'!B7 -> 9293.991 | C4: ='US Raw Data'!C7 -> 1835.085 | D4: ='US Raw Data'!D7 -> 1814.518 | E4: ='US Raw Data'!E7 -> 360.088 | F4: =D4-E4 -> 1454.43 | G4: ='US Raw Data'!F7*(B4*4/100) -> 22456.87 | H4: =F4-C4+E4+G3 -> 22084.204 | I4: =G4-H4 -> 372.66608 | J4: =F4-C4+E4+J3 -> 22151.263 | K4: =F4-C4+E4+I4+K3 -> 22456.87 | M4: =400*F4/(4*B4) -> 15.649144 | N4: =400*C4/(4*B4) -> 19.744854 | O4: =100*G4/(4*B4) -> 60.40696 | P4: =100*G3/(4*B4) -> 59.459845 | Q4: =400*E4/(4*B4)*(1/(P4/100)) -> 6.5160233 | R4: =400*I4/(4*B4) -> 4.009753 | S4: =(1/4)*(M4-N4+R4)+(1+(Q4/400))*P4 -> 60.40696 | T4: =(1/4)*(M4-N4+R4)+(1+(Q4/400))*T3 -> 61.552405 | U4: =T4*(B3/B4) -> 60.40736
A5: ='US Raw Data'!A8 -> 1999-Q1 | B5: ='US Raw Data'!B8 -> 9411.682 | C5: ='US Raw Data'!C8 -> 1860.002 | D5: ='US Raw Data'!D8 -> 1811.988 | E5: ='US Raw Data'!E8 -> 352.596 | F5: =D5-E5 -> 1459.392 | G5: ='US Raw Data'!F8*(B5*4/100) -> 22606.461 | H5: =F5-C5+E5+G4 -> 22408.856 | I5: =G5-H5 -> 197.60541 | J5: =F5-C5+E5+J4 -> 22103.249 | K5: =F5-C5+E5+I5+K4 -> 22606.461 | M5: =400*F5/(4*B5) -> 15.506176 | N5: =400*C5/(4*B5) -> 19.762695 | O5: =100*G5/(4*B5) -> 60.04894 | P5: =100*G4/(4*B5) -> 59.651584 | Q5: =400*E5/(4*B5)*(1/(P5/100)) -> 6.2804123 | R5: =400*I5/(4*B5) -> 2.0995759 | S5: =(1/4)*(M5-N5+R5)+(1+(Q5/400))*P5 -> 60.04894 | T5: =(1/4)*(M5-N5+R5)+(1+(Q5/400))*U4 -> 60.816582 | U5: =T5*(B4/B5) -> 60.056084
A6: ='US Raw Data'!A9 -> 1999-Q2 | B6: ='US Raw Data'!B9 -> 9526.21 | C6: ='US Raw Data'!C9 -> 1885.184 | D6: ='US Raw Data'!D9 -> 1816.961 | E6: ='US Raw Data'!E9 -> 352.141 | F6: =D6-E6 -> 1464.82 | G6: ='US Raw Data'!F9*(B6*4/100) -> 22555.12 | H6: =F6-C6+E6+G5 -> 22538.238 | I6: =G6-H6 -> 16.881667 | J6: =F6-C6+E6+J5 -> 22035.026 | K6: =F6-C6+E6+I6+K5 -> 22555.12 | M6: =400*F6/(4*B6) -> 15.376734 | N6: =400*C6/(4*B6) -> 19.789444 | O6: =100*G6/(4*B6) -> 59.19227 | P6: =100*G5/(4*B6) -> 59.327007 | Q6: =400*E6/(4*B6)*(1/(P6/100)) -> 6.2308027 | R6: =400*I6/(4*B6) -> 0.17721284 | S6: =(1/4)*(M6-N6+R6)+(1+(Q6/400))*P6 -> 59.19227 | T6: =(1/4)*(M6-N6+R6)+(1+(Q6/400))*U5 -> 59.932704 | U6: =T6*(B5/B6) -> 59.212168
A7: ='US Raw Data'!A10 -> 1999-Q3 | B7: ='US Raw Data'!B10 -> 9686.626 | C7: ='US Raw Data'!C10 -> 1914.862 | D7: ='US Raw Data'!D10 -> 1843.205 | E7: ='US Raw Data'!E10 -> 351.073 | F7: =D7-E7 -> 1492.132 | G7: ='US Raw Data'!F10*(B7*4/100) -> 22625.083 | H7: =F7-C7+E7+G6 -> 22483.463 | I7: =G7-H7 -> 141.62057 | J7: =F7-C7+E7+J6 -> 21963.369 | K7: =F7-C7+E7+I7+K6 -> 22625.083 | M7: =400*F7/(4*B7) -> 15.404043 | N7: =400*C7/(4*B7) -> 19.768101 | O7: =100*G7/(4*B7) -> 58.39258 | P7: =100*G6/(4*B7) -> 58.212013 | Q7: =400*E7/(4*B7)*(1/(P7/100)) -> 6.2260454 | R7: =400*I7/(4*B7) -> 1.4620217 | S7: =(1/4)*(M7-N7+R7)+(1+(Q7/400))*P7 -> 58.39258 | T7: =(1/4)*(M7-N7+R7)+(1+(Q7/400))*U6 -> 59.408303 | U7: =T7*(B6/B7) -> 58.424468
A8: ='US Raw Data'!A11 -> 1999-Q4 | B8: ='US Raw Data'!B11 -> 9900.169 | C8: ='US Raw Data'!C11 -> 1963.756 | D8: ='US Raw Data'!D11 -> 1875.154 | E8: ='US Raw Data'!E11 -> 352.925 | F8: =D8-E8 -> 1522.229 | G8: ='US Raw Data'!F11*(B8*4/100) -> 23104.365 | H8: =F8-C8+E8+G7 -> 22536.481 | I8: =G8-H8 -> 567.88362 | J8: =F8-C8+E8+J7 -> 21874.767 | K8: =F8-C8+E8+I8+K7 -> 23104.365 | M8: =400*F8/(4*B8) -> 15.375788 | N8: =400*C8/(4*B8) -> 19.835581 | O8: =100*G8/(4*B8) -> 58.34336 | P8: =100*G7/(4*B8) -> 57.133074 | Q8: =400*E8/(4*B8)*(1/(P8/100)) -> 6.239535 | R8: =400*I8/(4*B8) -> 5.7361002 | S8: =(1/4)*(M8-N8+R8)+(1+(Q8/400))*P8 -> 58.34336 | T8: =(1/4)*(M8-N8+R8)+(1+(Q8/400))*U7 -> 59.654899 | U8: =T8*(B7/B8) -> 58.368165
A9: ='US Raw Data'!A12 -> 2000-Q1 | B9: ='US Raw Data'!B12 -> 10002.179 | C9: ='US Raw Data'!C12 -> 2041.764 | D9: ='US Raw Data'!D12 -> 1866.308 | E9: ='US Raw Data'!E12 -> 354.822 | F9: =D9-E9 -> 1511.486 | G9: ='US Raw Data'!F12*(B9*4/100) -> 23093.567 | H9: =F9-C9+E9+G8 -> 22928.909 | I9: =G9-H9 -> 164.65803 | J9: =F9-C9+E9+J8 -> 21699.311 | K9: =F9-C9+E9+I9+K8 -> 23093.567 | M9: =400*F9/(4*B9) -> 15.111567 | N9: =400*C9/(4*B9) -> 20.413192 | O9: =100*G9/(4*B9) -> 57.72134 | P9: =100*G8/(4*B9) -> 57.748329 | Q9: =400*E9/(4*B9)*(1/(P9/100)) -> 6.1429431 | R9: =400*I9/(4*B9) -> 1.6462216 | S9: =(1/4)*(M9-N9+R9)+(1+(Q9/400))*P9 -> 57.72134 | T9: =(1/4)*(M9-N9+R9)+(1+(Q9/400))*U8 -> 58.350695 | U9: =T9*(B8/B9) -> 57.755589
A10: ='US Raw Data'!A13 -> 2000-Q2 | B10: ='US Raw Data'!B13 -> 10247.72 | C10: ='US Raw Data'!C13 -> 2056.279 | D10: ='US Raw Data'!D13 -> 1908.645 | E10: ='US Raw Data'!E13 -> 354.109 | F10: =D10-E10 -> 1554.536 | G10: ='US Raw Data'!F13*(B10*4/100) -> 22743.753 | H10: =F10-C10+E10+G9 -> 22945.933 | I10: =G10-H10 -> -202.18012 | J10: =F10-C10+E10+J9 -> 21551.677 | K10: =F10-C10+E10+I10+K9 -> 22743.753 | M10: =400*F10/(4*B10) -> 15.169579 | N10: =400*C10/(4*B10) -> 20.065722 | O10: =100*G10/(4*B10) -> 55.48491 | P10: =100*G9/(4*B10) -> 56.338305 | Q10: =400*E10/(4*B10)*(1/(P10/100)) -> 6.1334657 | R10: =400*I10/(4*B10) -> -1.9729278 | S10: =(1/4)*(M10-N10+R10)+(1+(Q10/400))*P10 -> 55.48491 | T10: =(1/4)*(M10-N10+R10)+(1+(Q10/400))*U9 -> 56.923926 | U10: =T10*(B9/B10) -> 55.559998
A11: ='US Raw Data'!A14 -> 2000-Q3 | B11: ='US Raw Data'!B14 -> 10318.165 | C11: ='US Raw Data'!C14 -> 2076.268 | D11: ='US Raw Data'!D14 -> 1918.617 | E11: ='US Raw Data'!E14 -> 352.877 | F11: =D11-E11 -> 1565.74 | G11: ='US Raw Data'!F14*(B11*4/100) -> 22696.715 | H11: =F11-C11+E11+G10 -> 22586.102 | I11: =G11-H11 -> 110.61297 | J11: =F11-C11+E11+J10 -> 21394.026 | K11: =F11-C11+E11+I11+K10 -> 22696.715 | M11: =400*F11/(4*B11) -> 15.174597 | N11: =400*C11/(4*B11) -> 20.122454 | O11: =100*G11/(4*B11) -> 54.99213 | P11: =100*G10/(4*B11) -> 55.106099 | Q11: =400*E11/(4*B11)*(1/(P11/100)) -> 6.206135 | R11: =400*I11/(4*B11) -> 1.0720217 | S11: =(1/4)*(M11-N11+R11)+(1+(Q11/400))*P11 -> 54.99213 | T11: =(1/4)*(M11-N11+R11)+(1+(Q11/400))*U10 -> 55.453071 | U11: =T11*(B10/B11) -> 55.074477
A12: ='US Raw Data'!A15 -> 2000-Q4 | B12: ='US Raw Data'!B15 -> 10435.744 | C12: ='US Raw Data'!C15 -> 2096.796 | D12: ='US Raw Data'!D15 -> 1938.796 | E12: ='US Raw Data'!E15 -> 353.105 | F12: =D12-E12 -> 1585.691 | G12: ='US Raw Data'!F15*(B12*4/100) -> 22648.862 | H12: =F12-C12+E12+G11 -> 22538.715 | I12: =G12-H12 -> 110.14733 | J12: =F12-C12+E12+J11 -> 21236.026 | K12: =F12-C12+E12+I12+K11 -> 22648.862 | M12: =400*F12/(4*B12) -> 15.194805 | N12: =400*C12/(4*B12) -> 20.092444 | O12: =100*G12/(4*B12) -> 54.2579 | P12: =100*G11/(4*B12) -> 54.372536 | Q12: =400*E12/(4*B12)*(1/(P12/100)) -> 6.2230151 | R12: =400*I12/(4*B12) -> 1.0554814 | S12: =(1/4)*(M12-N12+R12)+(1+(Q12/400))*P12 -> 54.2579 | T12: =(1/4)*(M12-N12+R12)+(1+(Q12/400))*U11 -> 54.970761 | U12: =T12*(B11/B12) -> 54.351409
A13: ='US Raw Data'!A16 -> 2001-Q1 | B13: ='US Raw Data'!B16 -> 10470.231 | C13: ='US Raw Data'!C16 -> 2111.058 | D13: ='US Raw Data'!D16 -> 1982.626 | E13: ='US Raw Data'!E16 -> 345.479 | F13: =D13-E13 -> 1637.147 | G13: ='US Raw Data'!F16*(B13*4/100) -> 23094.959 | H13: =F13-C13+E13+G12 -> 22520.43 | I13: =G13-H13 -> 574.52895 | J13: =F13-C13+E13+J12 -> 21107.594 | K13: =F13-C13+E13+I13+K12 -> 23094.959 | M13: =400*F13/(4*B13) -> 15.636207 | N13: =400*C13/(4*B13) -> 20.162478 | O13: =100*G13/(4*B13) -> 55.14434 | P13: =100*G12/(4*B13) -> 54.079185 | Q13: =400*E13/(4*B13)*(1/(P13/100)) -> 6.1014809 | R13: =400*I13/(4*B13) -> 5.4872615 | S13: =(1/4)*(M13-N13+R13)+(1+(Q13/400))*P13 -> 55.14434 | T13: =(1/4)*(M13-N13+R13)+(1+(Q13/400))*U12 -> 55.420716 | U13: =T13*(B12/B13) -> 55.238171
A14: ='US Raw Data'!A17 -> 2001-Q2 | B14: ='US Raw Data'!B17 -> 10599 | C14: ='US Raw Data'!C17 -> 2098.359 | D14: ='US Raw Data'!D17 -> 2003.581 | E14: ='US Raw Data'!E17 -> 334.776 | F14: =D14-E14 -> 1668.805 | G14: ='US Raw Data'!F17*(B14*4/100) -> 22907.258 | H14: =F14-C14+E14+G13 -> 23000.181 | I14: =G14-H14 -> -92.922792 | J14: =F14-C14+E14+J13 -> 21012.816 | K14: =F14-C14+E14+I14+K13 -> 22907.258 | M14: =400*F14/(4*B14) -> 15.744929 | N14: =400*C14/(4*B14) -> 19.797707 | O14: =100*G14/(4*B14) -> 54.03165 | P14: =100*G13/(4*B14) -> 54.474382 | Q14: =400*E14/(4*B14)*(1/(P14/100)) -> 5.7982523 | R14: =400*I14/(4*B14) -> -0.87671282 | S14: =(1/4)*(M14-N14+R14)+(1+(Q14/400))*P14 -> 54.03165 | T14: =(1/4)*(M14-N14+R14)+(1+(Q14/400))*U13 -> 54.80651 | U14: =T14*(B13/B14) -> 54.140657
A15: ='US Raw Data'!A18 -> 2001-Q3 | B15: ='US Raw Data'!B18 -> 10598.02 | C15: ='US Raw Data'!C18 -> 1907.679 | D15: ='US Raw Data'!D18 -> 2037.703 | E15: ='US Raw Data'!E18 -> 326.826 | F15: =D15-E15 -> 1710.877 | G15: ='US Raw Data'!F18*(B15*4/100) -> 23229.855 | H15: =F15-C15+E15+G14 -> 23037.282 | I15: =G15-H15 -> 192.57281 | J15: =F15-C15+E15+J14 -> 21142.84 | K15: =F15-C15+E15+I15+K14 -> 23229.855 | M15: =400*F15/(4*B15) -> 16.143365 | N15: =400*C15/(4*B15) -> 18.000334 | O15: =100*G15/(4*B15) -> 54.79763 | P15: =100*G14/(4*B15) -> 54.036646 | Q15: =400*E15/(4*B15)*(1/(P15/100)) -> 5.7069422 | R15: =400*I15/(4*B15) -> 1.8170641 | S15: =(1/4)*(M15-N15+R15)+(1+(Q15/400))*P15 -> 54.79763 | T15: =(1/4)*(M15-N15+R15)+(1+(Q15/400))*U14 -> 54.903124 | U15: =T15*(B14/B15) -> 54.908201
A16: ='US Raw Data'!A19 -> 2001-Q4 | B16: ='US Raw Data'!B19 -> 10660.465 | C16: ='US Raw Data'!C19 -> 2012.375 | D16: ='US Raw Data'!D19 -> 2045.404 | E16: ='US Raw Data'!E19 -> 317.821 | F16: =D16-E16 -> 1727.583 | G16: ='US Raw Data'!F19*(B16*4/100) -> 23773.758 | H16: =F16-C16+E16+G15 -> 23262.884 | I16: =G16-H16 -> 510.87387 | J16: =F16-C16+E16+J15 -> 21175.869 | K16: =F16-C16+E16+I16+K15 -> 23773.758 | M16: =400*F16/(4*B16) -> 16.205513 | N16: =400*C16/(4*B16) -> 18.876991 | O16: =100*G16/(4*B16) -> 55.75216 | P16: =100*G15/(4*B16) -> 54.476646 | Q16: =400*E16/(4*B16)*(1/(P16/100)) -> 5.4726299 | R16: =400*I16/(4*B16) -> 4.7922287 | S16: =(1/4)*(M16-N16+R16)+(1+(Q16/400))*P16 -> 55.75216 | T16: =(1/4)*(M16-N16+R16)+(1+(Q16/400))*U15 -> 56.18962 | U16: =T16*(B15/B16) -> 55.860482
... A112: ='US Raw Data'!A115 -> 2025-Q4 | B112: ='US Raw Data'!B115 -> 31422.526 | C112: ='US Raw Data'!C115 -> 5898.479 | D112: ='US Raw Data'!D115 -> 7583.663 | E112: ='US Raw Data'!E115 -> 1227.495 | F112: =D112-E112 -> 6356.168 | G112: ='US Raw Data'!F115*(B112*4/100) -> 154056.04 | H112: =F112-C112+E112+G111 -> 152235.4 | I112: =G112-H112 -> 1820.6378 | J112: =F112-C112+E112+J111 -> 120026.83 | K112: =F112-C112+E112+I112+K111 -> 154056.04 | M112: =400*F112/(4*B112) -> 20.228062 | N112: =400*C112/(4*B112) -> 18.771499 | O112: =100*G112/(4*B112) -> 122.56815 | P112: =100*G111/(4*B112) -> 119.77889 | Q112: =400*E112/(4*B112)*(1/(P112/100)) -> 3.2613571 | R112: =400*I112/(4*B112) -> 5.794053 | S112: =(1/4)*(M112-N112+R112)+(1+(Q112/400))*P112 -> 122.56815 | T112: =(1/4)*(M112-N112+R112)+(1+(Q112/400))*U111 -> 124.09977 | U112: =T112*(B111/B112) -> 122.8182

Sheet UScalc_LagY
A1: Quarter | B1: GDPN | C1: TAX | D1: GEXP+INTEXP | E1: INTEXP | F1: GEXP | G1: DEBT | H1: DEBTCheck1 | I1: RESID | J1: DEBTCheck2 | K1: DEBTCheck3 | M1: GEXPSHR | N1: TAXSHR | O1: DEBTG | P1: DEBTGLag | Q1: Ieff | R1: FFLOWSHR | S1: DEBTcheck Static | U1: DEBTcheck Dynamic | AG1: Is DEBTG end of period?
A2: ='US Raw Data'!A5 -> 1998-Q2 | B2: ='US Raw Data'!B5 -> 8969.699 | C2: ='US Raw Data'!C5 -> 1771.548 | D2: ='US Raw Data'!D5 -> 1781.911 | E2: ='US Raw Data'!E5 -> 367.648 | F2: =D2-E2 -> 1414.263 | G2: ='US Raw Data'!F5*(B2*4/100) -> 22191.739 | O2: =100*G2/(4*B2) -> 61.85196 | P2: NaN | Q2: NaN | R2: NaN | S2: GDP(t-1) | T2: GDP(t) | U2: GDP(t-1) | V2: GDP(t) | AG2: Are expenditures includig or excluding interest rate component?
A3: ='US Raw Data'!A6 -> 1998-Q3 | B3: ='US Raw Data'!B6 -> 9121.097 | C3: ='US Raw Data'!C6 -> 1808.447 | D3: ='US Raw Data'!D6 -> 1788.538 | E3: ='US Raw Data'!E6 -> 366.204 | F3: =D3-E3 -> 1422.334 | G3: ='US Raw Data'!F6*(B3*4/100) -> 22104.771 | H3: =F3-C3+E3+G2 -> 22171.83 | I3: =G3-H3 -> -67.058932 | J3: =F3-C3+E3+G2 -> 22171.83 | K3: =F3-C3+E3+I3+G2 -> 22104.771 | M3: =400*F3/(4*B2) -> 15.857098 | N3: =400*C3/(4*B2) -> 20.161736 | O3: =100*G3/(4*B3) -> 60.58693 | P3: =100*G3/(4*B2) -> 61.609566 | Q3: =400*E3/(4*B2)*(1/(O2/100)) -> 6.6007266 | R3: =400*I3/(4*B2) -> -0.7476163 | S3: =((1/4)*(M3-N3+R3)+(1+(Q3/400))*O2) -> 61.609566 | T3: =((1/4)*(M3-N3+R3)+(1+(Q3/400))*O2)*(B2/B3) -> 60.58693 | U3: =(1/4)*(M3-N3+R3)+(1+(Q3/400))*O2 -> 61.609566 | V3: =U3*(B2/B3) -> 60.58693
A4: ='US Raw Data'!A7 -> 1998-Q4 | B4: ='US Raw Data'!B7 -> 9293.991 | C4: ='US Raw Data'!C7 -> 1835.085 | D4: ='US Raw Data'!D7 -> 1814.518 | E4: ='US Raw Data'!E7 -> 360.088 | F4: =D4-E4 -> 1454.43 | G4: ='US Raw Data'!F7*(B4*4/100) -> 22456.87 | H4: =F4-C4+E4+G3 -> 22084.204 | I4: =G4-H4 -> 372.66608 | J4: =F4-C4+E4+J3 -> 22151.263 | K4: =F4-C4+E4+I4+K3 -> 22456.87 | M4: =400*F4/(4*B3) -> 15.945779 | N4: =400*C4/(4*B3) -> 20.119126 | O4: =100*G4/(4*B4) -> 60.40696 | P4: =100*G4/(4*B3) -> 61.551998 | Q4: =400*E4/(4*B3)*(1/(O3/100)) -> 6.5160233 | R4: =400*I4/(4*B3) -> 4.0857595 | S4: =((1/4)*(M4-N4+R4)+(1+(Q4/400))*O3) -> 61.551998 | T4: =((1/4)*(M4-N4+R4)+(1+(Q4/400))*O3)*(B3/B4) -> 60.40696 | U4: =(1/4)*(M4-N4+R4)+(1+(Q4/400))*V3 -> 61.551998 | V4: =U4*(B3/B4) -> 60.40696
A5: ='US Raw Data'!A8 -> 1999-Q1 | B5: ='US Raw Data'!B8 -> 9411.682 | C5: ='US Raw Data'!C8 -> 1860.002 | D5: ='US Raw Data'!D8 -> 1811.988 | E5: ='US Raw Data'!E8 -> 352.596 | F5: =D5-E5 -> 1459.392 | G5: ='US Raw Data'!F8*(B5*4/100) -> 22606.461 | H5: =F5-C5+E5+G4 -> 22408.856 | I5: =G5-H5 -> 197.60541 | J5: =F5-C5+E5+J4 -> 22103.249 | K5: =F5-C5+E5+I5+K4 -> 22606.461 | M5: =400*F5/(4*B4) -> 15.702533 | N5: =400*C5/(4*B4) -> 20.012952 | O5: =100*G5/(4*B5) -> 60.04894 | P5: =100*G5/(4*B4) -> 60.809347 | Q5: =400*E5/(4*B4)*(1/(O4/100)) -> 6.2804123 | R5: =400*I5/(4*B4) -> 2.1261631 | S5: =((1/4)*(M5-N5+R5)+(1+(Q5/400))*O4) -> 60.809347 | T5: =((1/4)*(M5-N5+R5)+(1+(Q5/400))*O4)*(B4/B5) -> 60.04894 | U5: =(1/4)*(M5-N5+R5)+(1+(Q5/400))*V4 -> 60.809347 | V5: =U5*(B4/B5) -> 60.04894
A6: ='US Raw Data'!A9 -> 1999-Q2 | B6: ='US Raw Data'!B9 -> 9526.21 | C6: ='US Raw Data'!C9 -> 1885.184 | D6: ='US Raw Data'!D9 -> 1816.961 | E6: ='US Raw Data'!E9 -> 352.141 | F6: =D6-E6 -> 1464.82 | G6: ='US Raw Data'!F9*(B6*4/100) -> 22555.12 | H6: =F6-C6+E6+G5 -> 22538.238 | I6: =G6-H6 -> 16.881667 | J6: =F6-C6+E6+J5 -> 22035.026 | K6: =F6-C6+E6+I6+K5 -> 22555.12 | M6: =400*F6/(4*B5) -> 15.563849 | N6: =400*C6/(4*B5) -> 20.030256 | O6: =100*G6/(4*B6) -> 59.19227 | P6: =100*G6/(4*B5) -> 59.912563 | Q6: =400*E6/(4*B5)*(1/(O5/100)) -> 6.2308027 | R6: =400*I6/(4*B5) -> 0.17936929 | S6: =((1/4)*(M6-N6+R6)+(1+(Q6/400))*O5) -> 59.912563 | T6: =((1/4)*(M6-N6+R6)+(1+(Q6/400))*O5)*(B5/B6) -> 59.19227 | U6: =(1/4)*(M6-N6+R6)+(1+(Q6/400))*V5 -> 59.912563 | V6: =U6*(B5/B6) -> 59.19227
A7: ='US Raw Data'!A10 -> 1999-Q3 | B7: ='US Raw Data'!B10 -> 9686.626 | C7: ='US Raw Data'!C10 -> 1914.862 | D7: ='US Raw Data'!D10 -> 1843.205 | E7: ='US Raw Data'!E10 -> 351.073 | F7: =D7-E7 -> 1492.132 | G7: ='US Raw Data'!F10*(B7*4/100) -> 22625.083 | H7: =F7-C7+E7+G6 -> 22483.463 | I7: =G7-H7 -> 141.62057 | J7: =F7-C7+E7+J6 -> 21963.369 | K7: =F7-C7+E7+I7+K6 -> 22625.083 | M7: =400*F7/(4*B6) -> 15.663438 | N7: =400*C7/(4*B6) -> 20.100985 | O7: =100*G7/(4*B7) -> 58.39258 | P7: =100*G7/(4*B6) -> 59.375878 | Q7: =400*E7/(4*B6)*(1/(O6/100)) -> 6.2260454 | R7: =400*I7/(4*B6) -> 1.4866413 | S7: =((1/4)*(M7-N7+R7)+(1+(Q7/400))*O6) -> 59.375878 | T7: =((1/4)*(M7-N7+R7)+(1+(Q7/400))*O6)*(B6/B7) -> 58.39258 | U7: =(1/4)*(M7-N7+R7)+(1+(Q7/400))*V6 -> 59.375878 | V7: =U7*(B6/B7) -> 58.39258
A8: ='US Raw Data'!A11 -> 1999-Q4 | B8: ='US Raw Data'!B11 -> 9900.169 | C8: ='US Raw Data'!C11 -> 1963.756 | D8: ='US Raw Data'!D11 -> 1875.154 | E8: ='US Raw Data'!E11 -> 352.925 | F8: =D8-E8 -> 1522.229 | G8: ='US Raw Data'!F11*(B8*4/100) -> 23104.365 | H8: =F8-C8+E8+G7 -> 22536.481 | I8: =G8-H8 -> 567.88362 | J8: =F8-C8+E8+J7 -> 21874.767 | K8: =F8-C8+E8+I8+K7 -> 23104.365 | M8: =400*F8/(4*B7) -> 15.714749 | N8: =400*C8/(4*B7) -> 20.272859 | O8: =100*G8/(4*B8) -> 58.34336 | P8: =100*G8/(4*B7) -> 59.629547 | Q8: =400*E8/(4*B7)*(1/(O7/100)) -> 6.239535 | R8: =400*I8/(4*B7) -> 5.8625533 | S8: =((1/4)*(M8-N8+R8)+(1+(Q8/400))*O7) -> 59.629547 | T8: =((1/4)*(M8-N8+R8)+(1+(Q8/400))*O7)*(B7/B8) -> 58.34336 | U8: =(1/4)*(M8-N8+R8)+(1+(Q8/400))*V7 -> 59.629547 | V8: =U8*(B7/B8) -> 58.34336
A9: ='US Raw Data'!A12 -> 2000-Q1 | B9: ='US Raw Data'!B12 -> 10002.179 | C9: ='US Raw Data'!C12 -> 2041.764 | D9: ='US Raw Data'!D12 -> 1866.308 | E9: ='US Raw Data'!E12 -> 354.822 | F9: =D9-E9 -> 1511.486 | G9: ='US Raw Data'!F12*(B9*4/100) -> 23093.567 | H9: =F9-C9+E9+G8 -> 22928.909 | I9: =G9-H9 -> 164.65803 | J9: =F9-C9+E9+J8 -> 21699.311 | K9: =F9-C9+E9+I9+K8 -> 23093.567 | M9: =400*F9/(4*B8) -> 15.267275 | N9: =400*C9/(4*B8) -> 20.623527 | O9: =100*G9/(4*B9) -> 57.72134 | P9: =100*G9/(4*B8) -> 58.316093 | Q9: =400*E9/(4*B8)*(1/(O8/100)) -> 6.1429431 | R9: =400*I9/(4*B8) -> 1.663184 | S9: =((1/4)*(M9-N9+R9)+(1+(Q9/400))*O8) -> 58.316093 | T9: =((1/4)*(M9-N9+R9)+(1+(Q9/400))*O8)*(B8/B9) -> 57.72134 | U9: =(1/4)*(M9-N9+R9)+(1+(Q9/400))*V8 -> 58.316093 | V9: =U9*(B8/B9) -> 57.72134
A10: ='US Raw Data'!A13 -> 2000-Q2 | B10: ='US Raw Data'!B13 -> 10247.72 | C10: ='US Raw Data'!C13 -> 2056.279 | D10: ='US Raw Data'!D13 -> 1908.645 | E10: ='US Raw Data'!E13 -> 354.109 | F10: =D10-E10 -> 1554.536 | G10: ='US Raw Data'!F13*(B10*4/100) -> 22743.753 | H10: =F10-C10+E10+G9 -> 22945.933 | I10: =G10-H10 -> -202.18012 | J10: =F10-C10+E10+J9 -> 21551.677 | K10: =F10-C10+E10+I10+K9 -> 22743.753 | M10: =400*F10/(4*B9) -> 15.541973 | N10: =400*C10/(4*B9) -> 20.55831 | O10: =100*G10/(4*B10) -> 55.48491 | P10: =100*G10/(4*B9) -> 56.846995 | Q10: =400*E10/(4*B9)*(1/(O9/100)) -> 6.1334657 | R10: =400*I10/(4*B9) -> -2.0213607 | S10: =((1/4)*(M10-N10+R10)+(1+(Q10/400))*O9) -> 56.846995 | T10: =((1/4)*(M10-N10+R10)+(1+(Q10/400))*O9)*(B9/B10) -> 55.48491 | U10: =(1/4)*(M10-N10+R10)+(1+(Q10/400))*V9 -> 56.846995 | V10: =U10*(B9/B10) -> 55.48491
A11: ='US Raw Data'!A14 -> 2000-Q3 | B11: ='US Raw Data'!B14 -> 10318.165 | C11: ='US Raw Data'!C14 -> 2076.268 | D11: ='US Raw Data'!D14 -> 1918.617 | E11: ='US Raw Data'!E14 -> 352.877 | F11: =D11-E11 -> 1565.74 | G11: ='US Raw Data'!F14*(B11*4/100) -> 22696.715 | H11: =F11-C11+E11+G10 -> 22586.102 | I11: =G11-H11 -> 110.61297 | J11: =F11-C11+E11+J10 -> 21394.026 | K11: =F11-C11+E11+I11+K10 -> 22696.715 | M11: =400*F11/(4*B10) -> 15.278911 | N11: =400*C11/(4*B10) -> 20.26078 | O11: =100*G11/(4*B11) -> 54.99213 | P11: =100*G11/(4*B10) -> 55.370158 | Q11: =400*E11/(4*B10)*(1/(O10/100)) -> 6.206135 | R11: =400*I11/(4*B10) -> 1.079391 | S11: =((1/4)*(M11-N11+R11)+(1+(Q11/400))*O10) -> 55.370158 | T11: =((1/4)*(M11-N11+R11)+(1+(Q11/400))*O10)*(B10/B11) -> 54.99213 | U11: =(1/4)*(M11-N11+R11)+(1+(Q11/400))*V10 -> 55.370158 | V11: =U11*(B10/B11) -> 54.99213
A12: ='US Raw Data'!A15 -> 2000-Q4 | B12: ='US Raw Data'!B15 -> 10435.744 | C12: ='US Raw Data'!C15 -> 2096.796 | D12: ='US Raw Data'!D15 -> 1938.796 | E12: ='US Raw Data'!E15 -> 353.105 | F12: =D12-E12 -> 1585.691 | G12: ='US Raw Data'!F15*(B12*4/100) -> 22648.862 | H12: =F12-C12+E12+G11 -> 22538.715 | I12: =G12-H12 -> 110.14733 | J12: =F12-C12+E12+J11 -> 21236.026 | K12: =F12-C12+E12+I12+K11 -> 22648.862 | M12: =400*F12/(4*B11) -> 15.367955 | N12: =400*C12/(4*B11) -> 20.321404 | O12: =100*G12/(4*B12) -> 54.2579 | P12: =100*G12/(4*B11) -> 54.876187 | Q12: =400*E12/(4*B11)*(1/(O11/100)) -> 6.2230151 | R12: =400*I12/(4*B11) -> 1.0675089 | S12: =((1/4)*(M12-N12+R12)+(1+(Q12/400))*O11) -> 54.876187 | T12: =((1/4)*(M12-N12+R12)+(1+(Q12/400))*O11)*(B11/B12) -> 54.2579 | U12: =(1/4)*(M12-N12+R12)+(1+(Q12/400))*V11 -> 54.876187 | V12: =U12*(B11/B12) -> 54.2579
A13: ='US Raw Data'!A16 -> 2001-Q1 | B13: ='US Raw Data'!B16 -> 10470.231 | C13: ='US Raw Data'!C16 -> 2111.058 | D13: ='US Raw Data'!D16 -> 1982.626 | E13: ='US Raw Data'!E16 -> 345.479 | F13: =D13-E13 -> 1637.147 | G13: ='US Raw Data'!F16*(B13*4/100) -> 23094.959 | H13: =F13-C13+E13+G12 -> 22520.43 | I13: =G13-H13 -> 574.52895 | J13: =F13-C13+E13+J12 -> 21107.594 | K13: =F13-C13+E13+I13+K12 -> 23094.959 | M13: =400*F13/(4*B12) -> 15.68788 | N13: =400*C13/(4*B12) -> 20.229109 | O13: =100*G13/(4*B13) -> 55.14434 | P13: =100*G13/(4*B12) -> 55.326575 | Q13: =400*E13/(4*B12)*(1/(O12/100)) -> 6.1014809 | R13: =400*I13/(4*B12) -> 5.5053952 | S13: =((1/4)*(M13-N13+R13)+(1+(Q13/400))*O12) -> 55.326575 | T13: =((1/4)*(M13-N13+R13)+(1+(Q13/400))*O12)*(B12/B13) -> 55.14434 | U13: =(1/4)*(M13-N13+R13)+(1+(Q13/400))*V12 -> 55.326575 | V13: =U13*(B12/B13) -> 55.14434
A14: ='US Raw Data'!A17 -> 2001-Q2 | B14: ='US Raw Data'!B17 -> 10599 | C14: ='US Raw Data'!C17 -> 2098.359 | D14: ='US Raw Data'!D17 -> 2003.581 | E14: ='US Raw Data'!E17 -> 334.776 | F14: =D14-E14 -> 1668.805 | G14: ='US Raw Data'!F17*(B14*4/100) -> 22907.258 | H14: =F14-C14+E14+G13 -> 23000.181 | I14: =G14-H14 -> -92.922792 | J14: =F14-C14+E14+J13 -> 21012.816 | K14: =F14-C14+E14+I14+K13 -> 22907.258 | M14: =400*F14/(4*B13) -> 15.938569 | N14: =400*C14/(4*B13) -> 20.041191 | O14: =100*G14/(4*B14) -> 54.03165 | P14: =100*G14/(4*B13) -> 54.696163 | Q14: =400*E14/(4*B13)*(1/(O13/100)) -> 5.7982523 | R14: =400*I14/(4*B13) -> -0.88749514 | S14: =((1/4)*(M14-N14+R14)+(1+(Q14/400))*O13) -> 54.696163 | T14: =((1/4)*(M14-N14+R14)+(1+(Q14/400))*O13)*(B13/B14) -> 54.03165 | U14: =(1/4)*(M14-N14+R14)+(1+(Q14/400))*V13 -> 54.696163 | V14: =U14*(B13/B14) -> 54.03165
A15: ='US Raw Data'!A18 -> 2001-Q3 | B15: ='US Raw Data'!B18 -> 10598.02 | C15: ='US Raw Data'!C18 -> 1907.679 | D15: ='US Raw Data'!D18 -> 2037.703 | E15: ='US Raw Data'!E18 -> 326.826 | F15: =D15-E15 -> 1710.877 | G15: ='US Raw Data'!F18*(B15*4/100) -> 23229.855 | H15: =F15-C15+E15+G14 -> 23037.282 | I15: =G15-H15 -> 192.57281 | J15: =F15-C15+E15+J14 -> 21142.84 | K15: =F15-C15+E15+I15+K14 -> 23229.855 | M15: =400*F15/(4*B14) -> 16.141872 | N15: =400*C15/(4*B14) -> 17.99867 | O15: =100*G15/(4*B15) -> 54.79763 | P15: =100*G15/(4*B14) -> 54.792563 | Q15: =400*E15/(4*B14)*(1/(O14/100)) -> 5.7069422 | R15: =400*I15/(4*B14) -> 1.8168961 | S15: =((1/4)*(M15-N15+R15)+(1+(Q15/400))*O14) -> 54.792563 | T15: =((1/4)*(M15-N15+R15)+(1+(Q15/400))*O14)*(B14/B15) -> 54.79763 | U15: =(1/4)*(M15-N15+R15)+(1+(Q15/400))*V14 -> 54.792563 | V15: =U15*(B14/B15) -> 54.79763
... A112: ='US Raw Data'!A115 -> 2025-Q4 | B112: ='US Raw Data'!B115 -> 31422.526 | C112: ='US Raw Data'!C115 -> 5898.479 | D112: ='US Raw Data'!D115 -> 7583.663 | E112: ='US Raw Data'!E115 -> 1227.495 | F112: =D112-E112 -> 6356.168 | G112: ='US Raw Data'!F115*(B112*4/100) -> 154056.04 | H112: =F112-C112+E112+G111 -> 152235.4 | I112: =G112-H112 -> 1820.6378 | J112: =F112-C112+E112+J111 -> 120026.83 | K112: =F112-C112+E112+I112+K111 -> 154056.04 | M112: =400*F112/(4*B111) -> 20.439136 | N112: =400*C112/(4*B111) -> 18.967374 | O112: =100*G112/(4*B112) -> 122.56815 | P112: =100*G112/(4*B111) -> 123.84711 | Q112: =400*E112/(4*B111)*(1/(O111/100)) -> 3.2613571 | R112: =400*I112/(4*B111) -> 5.8545122 | S112: =((1/4)*(M112-N112+R112)+(1+(Q112/400))*O111) -> 123.84711 | T112: =((1/4)*(M112-N112+R112)+(1+(Q112/400))*O111)*(B111/B112) -> 122.56815 | U112: =(1/4)*(M112-N112+R112)+(1+(Q112/400))*V111 -> 123.84711 | V112: =U112*(B111/B112) -> 122.56815

Sheet US Construction
A1: US CONSTRUCTION - BVAR fiscal inputs from raw cells (LIVE FORMULAS)
A2: Every value is a LIVE formula referencing 'US Raw Data'. US flows are SAAR (already annual): ratios are flow_t/GDP_t with NO *4. Lags reference the row ABOVE on Raw Data; the first row here is 1998Q3 (1998Q2 sits on Raw Data only to supply that lag). Column C is the RAW (no-COVID) FPEXP; column D is the FPEXP that ACTUALLY entered the BVAR (= raw, except interpolated across 2020Q2-2021Q4). FREV (B) and DSVC (G) are untreated.
A4: Date | B4: FREV_GDP (% GDP) | C4: FPEXP_GDP RAW (% GDP) | D4: FPEXP_GDP into BVAR (% GDP) | E4: net interest ($bn) | F4: EFFI (% p.a.) | G4: d_{t-1} (% GDP) | H4: DSVC (% GDP)
B5: FREV = FGRECPT / GDP * 100 | C5: raw primary exp = (FGEXPND - A091) / GDP * 100 [no COVID treatment] | D5: = raw, EXCEPT linearly interpolated across 2020Q2-2021Q4 (COVID outlier) | E5: = A091 (SAAR) - the debt-service $ cost | F5: EFFI = A091 / [ (debt/GDP_{t-1}/100) * GDP_{t-1} ] * 100 | G5: = GFDEGDQ188S of the previous quarter (lagged debt ratio) | H5: DSVC = A091 / GDP_{t-1} * 100 = EFFI * d_{t-1}/100 (DEBT SERVICE)
A6: ='US Raw Data'!A6 -> 1998-Q3 | B6: ='US Raw Data'!C6/'US Raw Data'!B6*100 -> 19.827078 | C6: =('US Raw Data'!D6-'US Raw Data'!E6)/'US Raw Data'!B6*100 -> 15.593892 | D6: =C6 -> 15.593892 | E6: ='US Raw Data'!E6 -> 366.204 | F6: ='US Raw Data'!E6/(('US Raw Data'!F5/100)*'US Raw Data'!B5)*100 -> 6.6007266 | G6: ='US Raw Data'!F5 -> 61.85196 | H6: ='US Raw Data'!E6/'US Raw Data'!B5*100 -> 4.0826788
A7: ='US Raw Data'!A7 -> 1998-Q4 | B7: ='US Raw Data'!C7/'US Raw Data'!B7*100 -> 19.744854 | C7: =('US Raw Data'!D7-'US Raw Data'!E7)/'US Raw Data'!B7*100 -> 15.649144 | D7: =C7 -> 15.649144 | E7: ='US Raw Data'!E7 -> 360.088 | F7: ='US Raw Data'!E7/(('US Raw Data'!F6/100)*'US Raw Data'!B6)*100 -> 6.5160233 | G7: ='US Raw Data'!F6 -> 60.58693 | H7: ='US Raw Data'!E7/'US Raw Data'!B6*100 -> 3.9478585
A8: ='US Raw Data'!A8 -> 1999-Q1 | B8: ='US Raw Data'!C8/'US Raw Data'!B8*100 -> 19.762695 | C8: =('US Raw Data'!D8-'US Raw Data'!E8)/'US Raw Data'!B8*100 -> 15.506176 | D8: =C8 -> 15.506176 | E8: ='US Raw Data'!E8 -> 352.596 | F8: ='US Raw Data'!E8/(('US Raw Data'!F7/100)*'US Raw Data'!B7)*100 -> 6.2804123 | G8: ='US Raw Data'!F7 -> 60.40696 | H8: ='US Raw Data'!E8/'US Raw Data'!B7*100 -> 3.7938061
A9: ='US Raw Data'!A9 -> 1999-Q2 | B9: ='US Raw Data'!C9/'US Raw Data'!B9*100 -> 19.789444 | C9: =('US Raw Data'!D9-'US Raw Data'!E9)/'US Raw Data'!B9*100 -> 15.376734 | D9: =C9 -> 15.376734 | E9: ='US Raw Data'!E9 -> 352.141 | F9: ='US Raw Data'!E9/(('US Raw Data'!F8/100)*'US Raw Data'!B8)*100 -> 6.2308027 | G9: ='US Raw Data'!F8 -> 60.04894 | H9: ='US Raw Data'!E9/'US Raw Data'!B8*100 -> 3.741531
A10: ='US Raw Data'!A10 -> 1999-Q3 | B10: ='US Raw Data'!C10/'US Raw Data'!B10*100 -> 19.768101 | C10: =('US Raw Data'!D10-'US Raw Data'!E10)/'US Raw Data'!B10*100 -> 15.404043 | D10: =C10 -> 15.404043 | E10: ='US Raw Data'!E10 -> 351.073 | F10: ='US Raw Data'!E10/(('US Raw Data'!F9/100)*'US Raw Data'!B9)*100 -> 6.2260454 | G10: ='US Raw Data'!F9 -> 59.19227 | H10: ='US Raw Data'!E10/'US Raw Data'!B9*100 -> 3.6853376
A11: ='US Raw Data'!A11 -> 1999-Q4 | B11: ='US Raw Data'!C11/'US Raw Data'!B11*100 -> 19.835581 | C11: =('US Raw Data'!D11-'US Raw Data'!E11)/'US Raw Data'!B11*100 -> 15.375788 | D11: =C11 -> 15.375788 | E11: ='US Raw Data'!E11 -> 352.925 | F11: ='US Raw Data'!E11/(('US Raw Data'!F10/100)*'US Raw Data'!B10)*100 -> 6.239535 | G11: ='US Raw Data'!F10 -> 58.39258 | H11: ='US Raw Data'!E11/'US Raw Data'!B10*100 -> 3.6434255
A12: ='US Raw Data'!A12 -> 2000-Q1 | B12: ='US Raw Data'!C12/'US Raw Data'!B12*100 -> 20.413192 | C12: =('US Raw Data'!D12-'US Raw Data'!E12)/'US Raw Data'!B12*100 -> 15.111567 | D12: =C12 -> 15.111567 | E12: ='US Raw Data'!E12 -> 354.822 | F12: ='US Raw Data'!E12/(('US Raw Data'!F11/100)*'US Raw Data'!B11)*100 -> 6.1429431 | G12: ='US Raw Data'!F11 -> 58.34336 | H12: ='US Raw Data'!E12/'US Raw Data'!B11*100 -> 3.5839994
A13: ='US Raw Data'!A13 -> 2000-Q2 | B13: ='US Raw Data'!C13/'US Raw Data'!B13*100 -> 20.065722 | C13: =('US Raw Data'!D13-'US Raw Data'!E13)/'US Raw Data'!B13*100 -> 15.169579 | D13: =C13 -> 15.169579 | E13: ='US Raw Data'!E13 -> 354.109 | F13: ='US Raw Data'!E13/(('US Raw Data'!F12/100)*'US Raw Data'!B12)*100 -> 6.1334657 | G13: ='US Raw Data'!F12 -> 57.72134 | H13: ='US Raw Data'!E13/'US Raw Data'!B12*100 -> 3.5403186
A14: ='US Raw Data'!A14 -> 2000-Q3 | B14: ='US Raw Data'!C14/'US Raw Data'!B14*100 -> 20.122454 | C14: =('US Raw Data'!D14-'US Raw Data'!E14)/'US Raw Data'!B14*100 -> 15.174597 | D14: =C14 -> 15.174597 | E14: ='US Raw Data'!E14 -> 352.877 | F14: ='US Raw Data'!E14/(('US Raw Data'!F13/100)*'US Raw Data'!B13)*100 -> 6.206135 | G14: ='US Raw Data'!F13 -> 55.48491 | H14: ='US Raw Data'!E14/'US Raw Data'!B13*100 -> 3.4434684
A15: ='US Raw Data'!A15 -> 2000-Q4 | B15: ='US Raw Data'!C15/'US Raw Data'!B15*100 -> 20.092444 | C15: =('US Raw Data'!D15-'US Raw Data'!E15)/'US Raw Data'!B15*100 -> 15.194805 | D15: =C15 -> 15.194805 | E15: ='US Raw Data'!E15 -> 353.105 | F15: ='US Raw Data'!E15/(('US Raw Data'!F14/100)*'US Raw Data'!B14)*100 -> 6.2230151 | G15: ='US Raw Data'!F14 -> 54.99213 | H15: ='US Raw Data'!E15/'US Raw Data'!B14*100 -> 3.4221686
A16: ='US Raw Data'!A16 -> 2001-Q1 | B16: ='US Raw Data'!C16/'US Raw Data'!B16*100 -> 20.162478 | C16: =('US Raw Data'!D16-'US Raw Data'!E16)/'US Raw Data'!B16*100 -> 15.636207 | D16: =C16 -> 15.636207 | E16: ='US Raw Data'!E16 -> 345.479 | F16: ='US Raw Data'!E16/(('US Raw Data'!F15/100)*'US Raw Data'!B15)*100 -> 6.1014809 | G16: ='US Raw Data'!F15 -> 54.2579 | H16: ='US Raw Data'!E16/'US Raw Data'!B15*100 -> 3.3105354
A17: ='US Raw Data'!A17 -> 2001-Q2 | B17: ='US Raw Data'!C17/'US Raw Data'!B17*100 -> 19.797707 | C17: =('US Raw Data'!D17-'US Raw Data'!E17)/'US Raw Data'!B17*100 -> 15.744929 | D17: =C17 -> 15.744929 | E17: ='US Raw Data'!E17 -> 334.776 | F17: ='US Raw Data'!E17/(('US Raw Data'!F16/100)*'US Raw Data'!B16)*100 -> 5.7982523 | G17: ='US Raw Data'!F16 -> 55.14434 | H17: ='US Raw Data'!E17/'US Raw Data'!B16*100 -> 3.197408
... A92: ='US Raw Data'!A92 -> 2020-Q1 | B92: ='US Raw Data'!C92/'US Raw Data'!B92*100 -> 17.429895 | C92: =('US Raw Data'!D92-'US Raw Data'!E92)/'US Raw Data'!B92*100 -> 19.872437 | D92: =C92 -> 19.872437 | E92: ='US Raw Data'!E92 -> 544.122 | F92: ='US Raw Data'!E92/(('US Raw Data'!F91/100)*'US Raw Data'!B91)*100 -> 2.3452139 | G92: ='US Raw Data'!F91 -> 105.78193 | H92: ='US Raw Data'!E92/'US Raw Data'!B91*100 -> 2.4808126
A93: ='US Raw Data'!A93 -> 2020-Q2 | B93: ='US Raw Data'!C93/'US Raw Data'!B93*100 -> 17.709487 | C93: =('US Raw Data'!D93-'US Raw Data'!E93)/'US Raw Data'!B93*100 -> 41.970708 | D93: =C92+(C100-C92)*0.125 -> 20.044705 | E93: ='US Raw Data'!E93 -> 514.737 | F93: ='US Raw Data'!E93/(('US Raw Data'!F92/100)*'US Raw Data'!B92)*100 -> 2.2164191 | G93: ='US Raw Data'!F92 -> 106.77007 | H93: ='US Raw Data'!E93/'US Raw Data'!B92*100 -> 2.3664722
A94: ='US Raw Data'!A94 -> 2020-Q3 | B94: ='US Raw Data'!C94/'US Raw Data'!B94*100 -> 17.496768 | C94: =('US Raw Data'!D94-'US Raw Data'!E94)/'US Raw Data'!B94*100 -> 30.713075 | D94: =C92+(C100-C92)*0.25 -> 20.216974 | E94: ='US Raw Data'!E94 -> 508.011 | F94: ='US Raw Data'!E94/(('US Raw Data'!F93/100)*'US Raw Data'!B93)*100 -> 1.9186704 | G94: ='US Raw Data'!F93 -> 132.66287 | H94: ='US Raw Data'!E94/'US Raw Data'!B93*100 -> 2.5453632
A95: ='US Raw Data'!A95 -> 2020-Q4 | B95: ='US Raw Data'!C95/'US Raw Data'!B95*100 -> 17.853617 | C95: =('US Raw Data'!D95-'US Raw Data'!E95)/'US Raw Data'!B95*100 -> 24.501258 | D95: =C92+(C100-C92)*0.375 -> 20.389243 | E95: ='US Raw Data'!E95 -> 516.711 | F95: ='US Raw Data'!E95/(('US Raw Data'!F94/100)*'US Raw Data'!B94)*100 -> 1.917623 | G95: ='US Raw Data'!F94 -> 124.14692 | H95: ='US Raw Data'!E95/'US Raw Data'!B94*100 -> 2.3806699
A96: ='US Raw Data'!A96 -> 2021-Q1 | B96: ='US Raw Data'!C96/'US Raw Data'!B96*100 -> 18.232873 | C96: =('US Raw Data'!D96-'US Raw Data'!E96)/'US Raw Data'!B96*100 -> 34.4468 | D96: =C92+(C100-C92)*0.5 -> 20.561512 | E96: ='US Raw Data'!E96 -> 533.518 | F96: ='US Raw Data'!E96/(('US Raw Data'!F95/100)*'US Raw Data'!B95)*100 -> 1.9227399 | G96: ='US Raw Data'!F95 -> 125.62864 | H96: ='US Raw Data'!E96/'US Raw Data'!B95*100 -> 2.415512
A97: ='US Raw Data'!A97 -> 2021-Q2 | B97: ='US Raw Data'!C97/'US Raw Data'!B97*100 -> 18.649581 | C97: =('US Raw Data'!D97-'US Raw Data'!E97)/'US Raw Data'!B97*100 -> 30.708267 | D97: =C92+(C100-C92)*0.625 -> 20.733781 | E97: ='US Raw Data'!E97 -> 560.634 | F97: ='US Raw Data'!E97/(('US Raw Data'!F96/100)*'US Raw Data'!B96)*100 -> 1.992829 | G97: ='US Raw Data'!F96 -> 124.03752 | H97: ='US Raw Data'!E97/'US Raw Data'!B96*100 -> 2.4718557
A98: ='US Raw Data'!A98 -> 2021-Q3 | B98: ='US Raw Data'!C98/'US Raw Data'!B98*100 -> 18.860264 | C98: =('US Raw Data'!D98-'US Raw Data'!E98)/'US Raw Data'!B98*100 -> 25.88438 | D98: =C92+(C100-C92)*0.75 -> 20.90605 | E98: ='US Raw Data'!E98 -> 587.92 | F98: ='US Raw Data'!E98/(('US Raw Data'!F97/100)*'US Raw Data'!B97)*100 -> 2.0607487 | G98: ='US Raw Data'!F97 -> 121.78582 | H98: ='US Raw Data'!E98/'US Raw Data'!B97*100 -> 2.5096997
A99: ='US Raw Data'!A99 -> 2021-Q4 | B99: ='US Raw Data'!C99/'US Raw Data'!B99*100 -> 18.89706 | C99: =('US Raw Data'!D99-'US Raw Data'!E99)/'US Raw Data'!B99*100 -> 22.679998 | D99: =C92+(C100-C92)*0.875 -> 21.078318 | E99: ='US Raw Data'!E99 -> 612.282 | F99: ='US Raw Data'!E99/(('US Raw Data'!F98/100)*'US Raw Data'!B98)*100 -> 2.1537295 | G99: ='US Raw Data'!F98 -> 118.54086 | H99: ='US Raw Data'!E99/'US Raw Data'!B98*100 -> 2.5530495
A100: ='US Raw Data'!A100 -> 2022-Q1 | B100: ='US Raw Data'!C100/'US Raw Data'!B100*100 -> 20.099177 | C100: =('US Raw Data'!D100-'US Raw Data'!E100)/'US Raw Data'!B100*100 -> 21.250587 | D100: =C100 -> 21.250587 | E100: ='US Raw Data'!E100 -> 636.968 | F100: ='US Raw Data'!E100/(('US Raw Data'!F99/100)*'US Raw Data'!B99)*100 -> 2.1506681 | G100: ='US Raw Data'!F99 -> 119.3588 | H100: ='US Raw Data'!E100/'US Raw Data'!B99*100 -> 2.5670116
A101: ='US Raw Data'!A101 -> 2022-Q2 | B101: ='US Raw Data'!C101/'US Raw Data'!B101*100 -> 19.85511 | C101: =('US Raw Data'!D101-'US Raw Data'!E101)/'US Raw Data'!B101*100 -> 20.860972 | D101: =C101 -> 20.860972 | E101: ='US Raw Data'!E101 -> 684.758 | F101: ='US Raw Data'!E101/(('US Raw Data'!F100/100)*'US Raw Data'!B100)*100 -> 2.2524222 | G101: ='US Raw Data'!F100 -> 120.39819 | H101: ='US Raw Data'!E101/'US Raw Data'!B100*100 -> 2.7118756
A102: ='US Raw Data'!A102 -> 2022-Q3 | B102: ='US Raw Data'!C102/'US Raw Data'!B102*100 -> 19.552546 | C102: =('US Raw Data'!D102-'US Raw Data'!E102)/'US Raw Data'!B102*100 -> 20.60523 | D102: =C102 -> 20.60523 | E102: ='US Raw Data'!E102 -> 752.081 | F102: ='US Raw Data'!E102/(('US Raw Data'!F101/100)*'US Raw Data'!B101)*100 -> 2.4603071 | G102: ='US Raw Data'!F101 -> 118.20207 | H102: ='US Raw Data'!E102/'US Raw Data'!B101*100 -> 2.9081339
A103: ='US Raw Data'!A103 -> 2022-Q4 | B103: ='US Raw Data'!C103/'US Raw Data'!B103*100 -> 19.061136 | C103: =('US Raw Data'!D103-'US Raw Data'!E103)/'US Raw Data'!B103*100 -> 20.527189 | D103: =C103 -> 20.527189 | E103: ='US Raw Data'!E103 -> 823.106 | F103: ='US Raw Data'!E103/(('US Raw Data'!F102/100)*'US Raw Data'!B102)*100 -> 2.6612833 | G103: ='US Raw Data'!F102 -> 117.43832 | H103: ='US Raw Data'!E103/'US Raw Data'!B102*100 -> 3.1253664
A104: ='US Raw Data'!A104 -> 2023-Q1 | B104: ='US Raw Data'!C104/'US Raw Data'!B104*100 -> 17.460014 | C104: =('US Raw Data'!D104-'US Raw Data'!E104)/'US Raw Data'!B104*100 -> 20.47414 | D104: =C104 -> 20.47414 | E104: ='US Raw Data'!E104 -> 861.267 | F104: ='US Raw Data'!E104/(('US Raw Data'!F103/100)*'US Raw Data'!B103)*100 -> 2.7411696 | G104: ='US Raw Data'!F103 -> 117.36678 | H104: ='US Raw Data'!E104/'US Raw Data'!B103*100 -> 3.2172225
A105: ='US Raw Data'!A105 -> 2023-Q2 | B105: ='US Raw Data'!C105/'US Raw Data'!B105*100 -> 17.324401 | C105: =('US Raw Data'!D105-'US Raw Data'!E105)/'US Raw Data'!B105*100 -> 20.332655 | D105: =C105 -> 20.332655 | E105: ='US Raw Data'!E105 -> 894.106 | F105: ='US Raw Data'!E105/(('US Raw Data'!F104/100)*'US Raw Data'!B104)*100 -> 2.8421818 | G105: ='US Raw Data'!F104 -> 115.58614 | H105: ='US Raw Data'!E105/'US Raw Data'!B104*100 -> 3.2851682
A106: ='US Raw Data'!A106 -> 2023-Q3 | B106: ='US Raw Data'!C106/'US Raw Data'!B106*100 -> 17.22377 | C106: =('US Raw Data'!D106-'US Raw Data'!E106)/'US Raw Data'!B106*100 -> 19.917245 | D106: =C106 -> 19.917245 | E106: ='US Raw Data'!E106 -> 966.899 | F106: ='US Raw Data'!E106/(('US Raw Data'!F105/100)*'US Raw Data'!B105)*100 -> 2.9905073 | G106: ='US Raw Data'!F105 -> 117.44355 | H106: ='US Raw Data'!E106/'US Raw Data'!B105*100 -> 3.5121579
A107: ='US Raw Data'!A107 -> 2023-Q4 | B107: ='US Raw Data'!C107/'US Raw Data'!B107*100 -> 17.331906 | C107: =('US Raw Data'!D107-'US Raw Data'!E107)/'US Raw Data'!B107*100 -> 19.830097 | D107: =C107 -> 19.830097 | E107: ='US Raw Data'!E107 -> 1031.478 | F107: ='US Raw Data'!E107/(('US Raw Data'!F106/100)*'US Raw Data'!B106)*100 -> 3.1099214 | G107: ='US Raw Data'!F106 -> 118.13897 | H107: ='US Raw Data'!E107/'US Raw Data'!B106*100 -> 3.6740291
A108: ='US Raw Data'!A108 -> 2024-Q1 | B108: ='US Raw Data'!C108/'US Raw Data'!B108*100 -> 17.576326 | C108: =('US Raw Data'!D108-'US Raw Data'!E108)/'US Raw Data'!B108*100 -> 20.116053 | D108: =C108 -> 20.116053 | E108: ='US Raw Data'!E108 -> 1071.174 | F108: ='US Raw Data'!E108/(('US Raw Data'!F107/100)*'US Raw Data'!B107)*100 -> 3.1503734 | G108: ='US Raw Data'!F107 -> 119.61944 | H108: ='US Raw Data'!E108/'US Raw Data'!B107*100 -> 3.768459
A109: ='US Raw Data'!A109 -> 2024-Q2 | B109: ='US Raw Data'!C109/'US Raw Data'!B109*100 -> 17.657015 | C109: =('US Raw Data'!D109-'US Raw Data'!E109)/'US Raw Data'!B109*100 -> 20.07221 | D109: =C109 -> 20.07221 | E109: ='US Raw Data'!E109 -> 1103.565 | F109: ='US Raw Data'!E109/(('US Raw Data'!F108/100)*'US Raw Data'!B108)*100 -> 3.1907361 | G109: ='US Raw Data'!F108 -> 120.47631 | H109: ='US Raw Data'!E109/'US Raw Data'!B108*100 -> 3.8440811
A110: ='US Raw Data'!A110 -> 2024-Q3 | B110: ='US Raw Data'!C110/'US Raw Data'!B110*100 -> 17.654426 | C110: =('US Raw Data'!D110-'US Raw Data'!E110)/'US Raw Data'!B110*100 -> 20.396956 | D110: =C110 -> 20.396956 | E110: ='US Raw Data'!E110 -> 1146.182 | F110: ='US Raw Data'!E110/(('US Raw Data'!F109/100)*'US Raw Data'!B109)*100 -> 3.2906353 | G110: ='US Raw Data'!F109 -> 119.50314 | H110: ='US Raw Data'!E110/'US Raw Data'!B109*100 -> 3.9324125
A111: ='US Raw Data'!A111 -> 2024-Q4 | B111: ='US Raw Data'!C111/'US Raw Data'!B111*100 -> 17.814453 | C111: =('US Raw Data'!D111-'US Raw Data'!E111)/'US Raw Data'!B111*100 -> 20.425847 | D111: =C111 -> 20.425847 | E111: ='US Raw Data'!E111 -> 1155.616 | F111: ='US Raw Data'!E111/(('US Raw Data'!F110/100)*'US Raw Data'!B110)*100 -> 3.2584988 | G111: ='US Raw Data'!F110 -> 120.17172 | H111: ='US Raw Data'!E111/'US Raw Data'!B110*100 -> 3.9157941
